{
 "cells": [
  {
   "cell_type": "code",
   "execution_count": 1,
   "id": "9e49d674",
   "metadata": {},
   "outputs": [
    {
     "name": "stdout",
     "output_type": "stream",
     "text": [
      "Model: \"sequential\"\n",
      "_________________________________________________________________\n",
      " Layer (type)                Output Shape              Param #   \n",
      "=================================================================\n",
      " conv2d (Conv2D)             (None, 62, 62, 32)        896       \n",
      "                                                                 \n",
      " max_pooling2d (MaxPooling2  (None, 31, 31, 32)        0         \n",
      " D)                                                              \n",
      "                                                                 \n",
      " conv2d_1 (Conv2D)           (None, 29, 29, 64)        18496     \n",
      "                                                                 \n",
      " max_pooling2d_1 (MaxPoolin  (None, 14, 14, 64)        0         \n",
      " g2D)                                                            \n",
      "                                                                 \n",
      " conv2d_2 (Conv2D)           (None, 12, 12, 128)       73856     \n",
      "                                                                 \n",
      " max_pooling2d_2 (MaxPoolin  (None, 6, 6, 128)         0         \n",
      " g2D)                                                            \n",
      "                                                                 \n",
      " flatten (Flatten)           (None, 4608)              0         \n",
      "                                                                 \n",
      " dense (Dense)               (None, 128)               589952    \n",
      "                                                                 \n",
      " dropout (Dropout)           (None, 128)               0         \n",
      "                                                                 \n",
      " dense_1 (Dense)             (None, 1)                 129       \n",
      "                                                                 \n",
      "=================================================================\n",
      "Total params: 683329 (2.61 MB)\n",
      "Trainable params: 683329 (2.61 MB)\n",
      "Non-trainable params: 0 (0.00 Byte)\n",
      "_________________________________________________________________\n"
     ]
    }
   ],
   "source": [
    "import tensorflow as tf\n",
    "from tensorflow.keras.layers import Conv2D, MaxPooling2D, Flatten, Dense, Dropout\n",
    "from tensorflow.keras.models import Sequential\n",
    "\n",
    "# Define the CNN model\n",
    "model = Sequential([\n",
    "    Conv2D(32, (3, 3), activation='relu', input_shape=(64, 64, 3)),\n",
    "    MaxPooling2D((2, 2)),\n",
    "    Conv2D(64, (3, 3), activation='relu'),\n",
    "    MaxPooling2D((2, 2)),\n",
    "    Conv2D(128, (3, 3), activation='relu'),\n",
    "    MaxPooling2D((2, 2)),\n",
    "    Flatten(),\n",
    "    Dense(128, activation='relu'),\n",
    "    Dropout(0.5),\n",
    "    Dense(1, activation='sigmoid')  # Output layer with sigmoid activation\n",
    "])\n",
    "\n",
    "# Compile the model\n",
    "model.compile(optimizer='adam', loss='binary_crossentropy', metrics=['accuracy'])\n",
    "\n",
    "# Print model summary\n",
    "model.summary()\n"
   ]
  },
  {
   "cell_type": "code",
   "execution_count": 10,
   "id": "8e357e6b",
   "metadata": {},
   "outputs": [],
   "source": [
    "import cv2\n",
    "import os\n",
    "\n",
    "# Directory containing your image dataset\n",
    "dataset_dir = 'C:/Users/Lenovo/Downloads/archive'\n",
    "\n",
    "# Initialize empty lists to store images and labels (if applicable)\n",
    "images = []\n",
    "labels = []\n",
    "\n",
    "\n",
    "# Loop through the files in the dataset directory\n",
    "for filename in os.listdir(dataset_dir):\n",
    "    if filename.endswith('.jpg'):  # You can adjust the file format as needed\n",
    "        image_path = os.path.join(dataset_dir, filename)\n",
    "        \n",
    "        # Load the image using OpenCV\n",
    "        image = cv2.imread(image_path)\n",
    "        \n",
    "        # If you have a folder structure with labels, you can extract the label from the path\n",
    "        label = os.path.basename(os.path.dirname(image_path))\n",
    "        \n",
    "        # Append the image and label to their respective lists\n",
    "        images.append(image)\n",
    "        labels.append(label)\n",
    "\n",
    "# Now 'images' contains a list of image arrays, and 'labels' contains corresponding labels (if applicable)\n"
   ]
  },
  {
   "cell_type": "code",
   "execution_count": 13,
   "id": "2fcba034",
   "metadata": {},
   "outputs": [],
   "source": [
    "import numpy as np\n",
    "from sklearn.model_selection import train_test_split\n",
    "import pandas as pd\n",
    "\n",
    "data = pd.read_csv('data.csv')\n",
    "\n",
    "X = data['images_id'].values\n",
    "y = data['label'].values\n",
    "# Split the dataset into training (80%) and temporary (20%)\n",
    "X_train_temp, X_temp, y_train_temp, y_temp = train_test_split(X, y, test_size=0.20, random_state=42)\n",
    "\n",
    "# Split the temporary dataset into validation (50%) and test (50%)\n",
    "X_val, X_test, y_val, y_test = train_test_split(X_temp, y_temp, test_size=0.50, random_state=42)\n",
    "\n"
   ]
  },
  {
   "cell_type": "code",
   "execution_count": 16,
   "id": "29651574",
   "metadata": {},
   "outputs": [
    {
     "name": "stdout",
     "output_type": "stream",
     "text": [
      "Epoch 1/10\n"
     ]
    },
    {
     "ename": "ValueError",
     "evalue": "in user code:\n\n    File \"C:\\Users\\Lenovo\\anaconda3\\Lib\\site-packages\\keras\\src\\engine\\training.py\", line 1338, in train_function  *\n        return step_function(self, iterator)\n    File \"C:\\Users\\Lenovo\\anaconda3\\Lib\\site-packages\\keras\\src\\engine\\training.py\", line 1322, in step_function  **\n        outputs = model.distribute_strategy.run(run_step, args=(data,))\n    File \"C:\\Users\\Lenovo\\anaconda3\\Lib\\site-packages\\keras\\src\\engine\\training.py\", line 1303, in run_step  **\n        outputs = model.train_step(data)\n    File \"C:\\Users\\Lenovo\\anaconda3\\Lib\\site-packages\\keras\\src\\engine\\training.py\", line 1080, in train_step\n        y_pred = self(x, training=True)\n    File \"C:\\Users\\Lenovo\\anaconda3\\Lib\\site-packages\\keras\\src\\utils\\traceback_utils.py\", line 70, in error_handler\n        raise e.with_traceback(filtered_tb) from None\n    File \"C:\\Users\\Lenovo\\anaconda3\\Lib\\site-packages\\keras\\src\\engine\\input_spec.py\", line 253, in assert_input_compatibility\n        raise ValueError(\n\n    ValueError: Exception encountered when calling layer 'sequential' (type Sequential).\n    \n    Input 0 of layer \"conv2d\" is incompatible with the layer: expected min_ndim=4, found ndim=1. Full shape received: (None,)\n    \n    Call arguments received by layer 'sequential' (type Sequential):\n      • inputs=tf.Tensor(shape=(None,), dtype=string)\n      • training=True\n      • mask=None\n",
     "output_type": "error",
     "traceback": [
      "\u001b[1;31m---------------------------------------------------------------------------\u001b[0m",
      "\u001b[1;31mValueError\u001b[0m                                Traceback (most recent call last)",
      "Cell \u001b[1;32mIn[16], line 2\u001b[0m\n\u001b[0;32m      1\u001b[0m \u001b[38;5;66;03m# Assuming you have 'X_train', 'y_train', 'X_val', 'y_val' prepared\u001b[39;00m\n\u001b[1;32m----> 2\u001b[0m model\u001b[38;5;241m.\u001b[39mfit(X_train_temp, y_train_temp, validation_data\u001b[38;5;241m=\u001b[39m(X_val, y_val), epochs\u001b[38;5;241m=\u001b[39m\u001b[38;5;241m10\u001b[39m, batch_size\u001b[38;5;241m=\u001b[39m\u001b[38;5;241m32\u001b[39m)\n",
      "File \u001b[1;32m~\\anaconda3\\Lib\\site-packages\\keras\\src\\utils\\traceback_utils.py:70\u001b[0m, in \u001b[0;36mfilter_traceback.<locals>.error_handler\u001b[1;34m(*args, **kwargs)\u001b[0m\n\u001b[0;32m     67\u001b[0m     filtered_tb \u001b[38;5;241m=\u001b[39m _process_traceback_frames(e\u001b[38;5;241m.\u001b[39m__traceback__)\n\u001b[0;32m     68\u001b[0m     \u001b[38;5;66;03m# To get the full stack trace, call:\u001b[39;00m\n\u001b[0;32m     69\u001b[0m     \u001b[38;5;66;03m# `tf.debugging.disable_traceback_filtering()`\u001b[39;00m\n\u001b[1;32m---> 70\u001b[0m     \u001b[38;5;28;01mraise\u001b[39;00m e\u001b[38;5;241m.\u001b[39mwith_traceback(filtered_tb) \u001b[38;5;28;01mfrom\u001b[39;00m \u001b[38;5;28;01mNone\u001b[39;00m\n\u001b[0;32m     71\u001b[0m \u001b[38;5;28;01mfinally\u001b[39;00m:\n\u001b[0;32m     72\u001b[0m     \u001b[38;5;28;01mdel\u001b[39;00m filtered_tb\n",
      "File \u001b[1;32m~\\AppData\\Local\\Temp\\__autograph_generated_filez8twwkom.py:15\u001b[0m, in \u001b[0;36mouter_factory.<locals>.inner_factory.<locals>.tf__train_function\u001b[1;34m(iterator)\u001b[0m\n\u001b[0;32m     13\u001b[0m \u001b[38;5;28;01mtry\u001b[39;00m:\n\u001b[0;32m     14\u001b[0m     do_return \u001b[38;5;241m=\u001b[39m \u001b[38;5;28;01mTrue\u001b[39;00m\n\u001b[1;32m---> 15\u001b[0m     retval_ \u001b[38;5;241m=\u001b[39m ag__\u001b[38;5;241m.\u001b[39mconverted_call(ag__\u001b[38;5;241m.\u001b[39mld(step_function), (ag__\u001b[38;5;241m.\u001b[39mld(\u001b[38;5;28mself\u001b[39m), ag__\u001b[38;5;241m.\u001b[39mld(iterator)), \u001b[38;5;28;01mNone\u001b[39;00m, fscope)\n\u001b[0;32m     16\u001b[0m \u001b[38;5;28;01mexcept\u001b[39;00m:\n\u001b[0;32m     17\u001b[0m     do_return \u001b[38;5;241m=\u001b[39m \u001b[38;5;28;01mFalse\u001b[39;00m\n",
      "\u001b[1;31mValueError\u001b[0m: in user code:\n\n    File \"C:\\Users\\Lenovo\\anaconda3\\Lib\\site-packages\\keras\\src\\engine\\training.py\", line 1338, in train_function  *\n        return step_function(self, iterator)\n    File \"C:\\Users\\Lenovo\\anaconda3\\Lib\\site-packages\\keras\\src\\engine\\training.py\", line 1322, in step_function  **\n        outputs = model.distribute_strategy.run(run_step, args=(data,))\n    File \"C:\\Users\\Lenovo\\anaconda3\\Lib\\site-packages\\keras\\src\\engine\\training.py\", line 1303, in run_step  **\n        outputs = model.train_step(data)\n    File \"C:\\Users\\Lenovo\\anaconda3\\Lib\\site-packages\\keras\\src\\engine\\training.py\", line 1080, in train_step\n        y_pred = self(x, training=True)\n    File \"C:\\Users\\Lenovo\\anaconda3\\Lib\\site-packages\\keras\\src\\utils\\traceback_utils.py\", line 70, in error_handler\n        raise e.with_traceback(filtered_tb) from None\n    File \"C:\\Users\\Lenovo\\anaconda3\\Lib\\site-packages\\keras\\src\\engine\\input_spec.py\", line 253, in assert_input_compatibility\n        raise ValueError(\n\n    ValueError: Exception encountered when calling layer 'sequential' (type Sequential).\n    \n    Input 0 of layer \"conv2d\" is incompatible with the layer: expected min_ndim=4, found ndim=1. Full shape received: (None,)\n    \n    Call arguments received by layer 'sequential' (type Sequential):\n      • inputs=tf.Tensor(shape=(None,), dtype=string)\n      • training=True\n      • mask=None\n"
     ]
    }
   ],
   "source": [
    "# Assuming you have 'X_train', 'y_train', 'X_val', 'y_val' prepared\n",
    "model.fit(X_train_temp, y_train_temp, validation_data=(X_val, y_val), epochs=10, batch_size=32)\n",
    " "
   ]
  },
  {
   "cell_type": "code",
   "execution_count": 15,
   "id": "1e1c3319",
   "metadata": {},
   "outputs": [
    {
     "ename": "ValueError",
     "evalue": "in user code:\n\n    File \"C:\\Users\\Lenovo\\anaconda3\\Lib\\site-packages\\keras\\src\\engine\\training.py\", line 1972, in test_function  *\n        return step_function(self, iterator)\n    File \"C:\\Users\\Lenovo\\anaconda3\\Lib\\site-packages\\keras\\src\\engine\\training.py\", line 1956, in step_function  **\n        outputs = model.distribute_strategy.run(run_step, args=(data,))\n    File \"C:\\Users\\Lenovo\\anaconda3\\Lib\\site-packages\\keras\\src\\engine\\training.py\", line 1944, in run_step  **\n        outputs = model.test_step(data)\n    File \"C:\\Users\\Lenovo\\anaconda3\\Lib\\site-packages\\keras\\src\\engine\\training.py\", line 1850, in test_step\n        y_pred = self(x, training=False)\n    File \"C:\\Users\\Lenovo\\anaconda3\\Lib\\site-packages\\keras\\src\\utils\\traceback_utils.py\", line 70, in error_handler\n        raise e.with_traceback(filtered_tb) from None\n    File \"C:\\Users\\Lenovo\\anaconda3\\Lib\\site-packages\\keras\\src\\engine\\input_spec.py\", line 253, in assert_input_compatibility\n        raise ValueError(\n\n    ValueError: Exception encountered when calling layer 'sequential' (type Sequential).\n    \n    Input 0 of layer \"conv2d\" is incompatible with the layer: expected min_ndim=4, found ndim=1. Full shape received: (None,)\n    \n    Call arguments received by layer 'sequential' (type Sequential):\n      • inputs=tf.Tensor(shape=(None,), dtype=string)\n      • training=False\n      • mask=None\n",
     "output_type": "error",
     "traceback": [
      "\u001b[1;31m---------------------------------------------------------------------------\u001b[0m",
      "\u001b[1;31mValueError\u001b[0m                                Traceback (most recent call last)",
      "Cell \u001b[1;32mIn[15], line 2\u001b[0m\n\u001b[0;32m      1\u001b[0m \u001b[38;5;66;03m# Assuming you have 'X_test' and 'y_test' prepared\u001b[39;00m\n\u001b[1;32m----> 2\u001b[0m test_loss, test_accuracy \u001b[38;5;241m=\u001b[39m model\u001b[38;5;241m.\u001b[39mevaluate(X_test, y_test)\n\u001b[0;32m      3\u001b[0m \u001b[38;5;28mprint\u001b[39m(\u001b[38;5;124mf\u001b[39m\u001b[38;5;124m\"\u001b[39m\u001b[38;5;124mTest Accuracy: \u001b[39m\u001b[38;5;132;01m{\u001b[39;00mtest_accuracy\u001b[38;5;250m \u001b[39m\u001b[38;5;241m*\u001b[39m\u001b[38;5;250m \u001b[39m\u001b[38;5;241m100\u001b[39m\u001b[38;5;132;01m:\u001b[39;00m\u001b[38;5;124m.2f\u001b[39m\u001b[38;5;132;01m}\u001b[39;00m\u001b[38;5;124m%\u001b[39m\u001b[38;5;124m\"\u001b[39m)\n",
      "File \u001b[1;32m~\\anaconda3\\Lib\\site-packages\\keras\\src\\utils\\traceback_utils.py:70\u001b[0m, in \u001b[0;36mfilter_traceback.<locals>.error_handler\u001b[1;34m(*args, **kwargs)\u001b[0m\n\u001b[0;32m     67\u001b[0m     filtered_tb \u001b[38;5;241m=\u001b[39m _process_traceback_frames(e\u001b[38;5;241m.\u001b[39m__traceback__)\n\u001b[0;32m     68\u001b[0m     \u001b[38;5;66;03m# To get the full stack trace, call:\u001b[39;00m\n\u001b[0;32m     69\u001b[0m     \u001b[38;5;66;03m# `tf.debugging.disable_traceback_filtering()`\u001b[39;00m\n\u001b[1;32m---> 70\u001b[0m     \u001b[38;5;28;01mraise\u001b[39;00m e\u001b[38;5;241m.\u001b[39mwith_traceback(filtered_tb) \u001b[38;5;28;01mfrom\u001b[39;00m \u001b[38;5;28;01mNone\u001b[39;00m\n\u001b[0;32m     71\u001b[0m \u001b[38;5;28;01mfinally\u001b[39;00m:\n\u001b[0;32m     72\u001b[0m     \u001b[38;5;28;01mdel\u001b[39;00m filtered_tb\n",
      "File \u001b[1;32m~\\AppData\\Local\\Temp\\__autograph_generated_filejypi4wtf.py:15\u001b[0m, in \u001b[0;36mouter_factory.<locals>.inner_factory.<locals>.tf__test_function\u001b[1;34m(iterator)\u001b[0m\n\u001b[0;32m     13\u001b[0m \u001b[38;5;28;01mtry\u001b[39;00m:\n\u001b[0;32m     14\u001b[0m     do_return \u001b[38;5;241m=\u001b[39m \u001b[38;5;28;01mTrue\u001b[39;00m\n\u001b[1;32m---> 15\u001b[0m     retval_ \u001b[38;5;241m=\u001b[39m ag__\u001b[38;5;241m.\u001b[39mconverted_call(ag__\u001b[38;5;241m.\u001b[39mld(step_function), (ag__\u001b[38;5;241m.\u001b[39mld(\u001b[38;5;28mself\u001b[39m), ag__\u001b[38;5;241m.\u001b[39mld(iterator)), \u001b[38;5;28;01mNone\u001b[39;00m, fscope)\n\u001b[0;32m     16\u001b[0m \u001b[38;5;28;01mexcept\u001b[39;00m:\n\u001b[0;32m     17\u001b[0m     do_return \u001b[38;5;241m=\u001b[39m \u001b[38;5;28;01mFalse\u001b[39;00m\n",
      "\u001b[1;31mValueError\u001b[0m: in user code:\n\n    File \"C:\\Users\\Lenovo\\anaconda3\\Lib\\site-packages\\keras\\src\\engine\\training.py\", line 1972, in test_function  *\n        return step_function(self, iterator)\n    File \"C:\\Users\\Lenovo\\anaconda3\\Lib\\site-packages\\keras\\src\\engine\\training.py\", line 1956, in step_function  **\n        outputs = model.distribute_strategy.run(run_step, args=(data,))\n    File \"C:\\Users\\Lenovo\\anaconda3\\Lib\\site-packages\\keras\\src\\engine\\training.py\", line 1944, in run_step  **\n        outputs = model.test_step(data)\n    File \"C:\\Users\\Lenovo\\anaconda3\\Lib\\site-packages\\keras\\src\\engine\\training.py\", line 1850, in test_step\n        y_pred = self(x, training=False)\n    File \"C:\\Users\\Lenovo\\anaconda3\\Lib\\site-packages\\keras\\src\\utils\\traceback_utils.py\", line 70, in error_handler\n        raise e.with_traceback(filtered_tb) from None\n    File \"C:\\Users\\Lenovo\\anaconda3\\Lib\\site-packages\\keras\\src\\engine\\input_spec.py\", line 253, in assert_input_compatibility\n        raise ValueError(\n\n    ValueError: Exception encountered when calling layer 'sequential' (type Sequential).\n    \n    Input 0 of layer \"conv2d\" is incompatible with the layer: expected min_ndim=4, found ndim=1. Full shape received: (None,)\n    \n    Call arguments received by layer 'sequential' (type Sequential):\n      • inputs=tf.Tensor(shape=(None,), dtype=string)\n      • training=False\n      • mask=None\n"
     ]
    }
   ],
   "source": [
    "# Assuming you have 'X_test' and 'y_test' prepared\n",
    "test_loss, test_accuracy = model.evaluate(X_test, y_test)\n",
    "print(f\"Test Accuracy: {test_accuracy * 100:.2f}%\")\n"
   ]
  },
  {
   "cell_type": "code",
   "execution_count": null,
   "id": "0ddf5fe8",
   "metadata": {},
   "outputs": [],
   "source": []
  }
 ],
 "metadata": {
  "kernelspec": {
   "display_name": "Python 3 (ipykernel)",
   "language": "python",
   "name": "python3"
  },
  "language_info": {
   "codemirror_mode": {
    "name": "ipython",
    "version": 3
   },
   "file_extension": ".py",
   "mimetype": "text/x-python",
   "name": "python",
   "nbconvert_exporter": "python",
   "pygments_lexer": "ipython3",
   "version": "3.11.4"
  }
 },
 "nbformat": 4,
 "nbformat_minor": 5
}
